<mujocoinclude>
    <body name="rm_65" pos="0.469 0.5 0">
        <geom type="mesh" mesh="base_link" name="rm_65/1_base" contype="0" conaffinity="0"/>
        <body name="rm_65/Link1" pos="0 0 0.2405">
            <inertial pos="1.22263e-08 0.021108 -0.0251854" quat="0.988851 -0.148906 -2.80074e-05 -0.000243475" mass="0.593563" diaginertia="0.00126614 0.00124677 0.000496264" />
            <joint name="rm_65/joint1" pos="0 0 0" axis="0 0 1" limited="true" range="-3.14 3.14" frictionloss="0.1"/>
            <geom type="mesh" rgba="1 1 1 1" mesh="link1" name="rm_65/link1" contype="0" conaffinity="0"/>
            <body name="rm_65/Link2" pos="0 0 0" quat="0.499998 0.5 -0.5 0.500002">
                <inertial pos="0.152256 4.75384e-07 -0.0062026" quat="1.2834e-05 0.785787 1.90512e-05 0.618497" mass="0.864175" diaginertia="0.00735632 0.00733754 0.000513875" />
                <joint name="rm_65/joint2" pos="0 0 0" axis="0 0 1" limited="true" range="-2.268 2.268" damping="0"  frictionloss="0.1" />
                <geom type="mesh" rgba="1 1 1 1" mesh="link2" name="rm_65/link2" contype="0" conaffinity="0"/>
                <body name="rm_65/Link3" pos="0.256 0 0" quat="0.707105 0 0 0.707108">
                    <inertial pos="5.05313e-06 -0.0595926 0.0105691" quat="0.424678 0.56496 -0.565554 0.424992" mass="0.289634" diaginertia="0.00065604 0.000637371 0.000114622" />
                    <joint name="rm_65/joint3" pos="0 0 0" axis="0 0 1" limited="true" range="-2.355 2.355" damping="0"  frictionloss="0.1" />
                    <geom type="mesh" rgba="1 1 1 1" mesh="link3" name="rm_65/link3" contype="0" conaffinity="0"/>
                    <body name="rm_65/Link4" pos="0 -0.21 0" quat="0.707105 0.707108 0 0">
                        <inertial pos="1.15517e-06 -0.0180424 -0.0215395" quat="0.990405 0.138195 -7.01319e-06 0.000110532" mass="0.23942" diaginertia="0.000285939 0.000275318 0.000107298" />
                        <joint name="rm_65/joint4" pos="0 0 0" axis="0 0 1" limited="true" range="-3.14 3.14" damping="0"  frictionloss="0.1"/>
                        <geom type="mesh" rgba="1 1 1 1" mesh="link4" name="rm_65/link4" contype="0" conaffinity="0"/>
                        <body name="rm_65/Link5" pos="0 0 0" quat="0.707105 -0.707108 0 0">
                            <inertial pos="3.19795e-06 -0.0593808 0.00736804" quat="0.419765 0.568659 -0.5692 0.420041" mass="0.2188" diaginertia="0.000358615 0.00035054 8.07958e-05" />
                            <joint name="rm_65/joint5" pos="0 0 0" axis="0 0 1" limited="true" range="-2.233 2.233"damping="0"  frictionloss="0.1" />
                            <geom type="mesh" rgba="1 1 1 1" mesh="link5" name="rm_65/link5" contype="0" conaffinity="0"/>
                            <body name="rm_65/Link6" pos="0 -0.144 0" quat="0.707105 0.707108 0 0">
                                <inertial pos="0.000714235 -0.000396719 -0.0126724" quat="0.613063 0.350717 -0.614301 0.351831" mass="0.0649018" diaginertia="3.17886e-05 2.10548e-05 1.80205e-05" />
                                <joint name="rm_65/joint6" pos="0 0 0" axis="0 0 1" limited="true" range="-6.28 6.28" damping="0"  frictionloss="0.1"/>
                                <geom type="mesh" rgba="1 1 1 1" mesh="link6" name="rm_65/link6" contype="0" conaffinity="0" />
                                <body name="rm_65/gripper_link" pos="0.069744 0 0" quat="0.707107 0 0 0.707107">
                                    <body name="rm_65/camera_focus" pos="0.15 0 0.01">
                                        <site pos="0 0 0" size="0.01" type="sphere" name="left_cam_focus" rgba="0 0 1 0"/>
                                    </body>
                                    <site pos="0.15 0 0" size="0.003 0.003 0.03" type="box" name="cali_left_site1" rgba="0 0 1 0"/>
                                    <site pos="0.15 0 0" size="0.003 0.03 0.003" type="box" name="cali_left_site2" rgba="0 0 1 0"/>
                                    <site pos="0.15 0 0" size="0.03 0.003 0.003" type="box" name="cali_left_site3" rgba="0 0 1 0"/>
                                    <camera name="left_wrist" pos="-0.1 0 0.16" fovy="20" mode="targetbody" target="rm_65/camera_focus"/>
                                </body>
                            </body>
                        </body>
                    </body>
                </body>
            </body>
        </body>
    </body>
</mujocoinclude>
